Traceback (most recent call last):
  File "/Users/tom/opt/anaconda3/envs/book/lib/python3.8/site-packages/jupyter_cache/executors/utils.py", line 51, in single_nb_execution
    executenb(
  File "/Users/tom/opt/anaconda3/envs/book/lib/python3.8/site-packages/nbclient/client.py", line 1112, in execute
    return NotebookClient(nb=nb, resources=resources, km=km, **kwargs).execute()
  File "/Users/tom/opt/anaconda3/envs/book/lib/python3.8/site-packages/nbclient/util.py", line 74, in wrapped
    return just_run(coro(*args, **kwargs))
  File "/Users/tom/opt/anaconda3/envs/book/lib/python3.8/site-packages/nbclient/util.py", line 53, in just_run
    return loop.run_until_complete(coro)
  File "/Users/tom/opt/anaconda3/envs/book/lib/python3.8/asyncio/base_events.py", line 616, in run_until_complete
    return future.result()
  File "/Users/tom/opt/anaconda3/envs/book/lib/python3.8/site-packages/nbclient/client.py", line 553, in async_execute
    await self.async_execute_cell(
  File "/Users/tom/opt/anaconda3/envs/book/lib/python3.8/site-packages/nbclient/client.py", line 857, in async_execute_cell
    self._check_raise_for_error(cell, exec_reply)
  File "/Users/tom/opt/anaconda3/envs/book/lib/python3.8/site-packages/nbclient/client.py", line 760, in _check_raise_for_error
    raise CellExecutionError.from_cell_and_msg(cell, exec_reply_content)
nbclient.exceptions.CellExecutionError: An error occurred while executing the following cell:
------------------
# Import custom code
import sys; from pathlib import Path
sys.path.append(str(Path('..').resolve()))

from apm.io import APMDB
from apm.run import run_sims, run_sims_load
from apm.methods import lyapunov
from apm.methods.settings import LY_PARAMS
from apm.plts.sims import plot_ap_sims, plot_pe_sims, plot_sims_two
from apm.plts.settings import COLORS
from apm.plts.utils import figsaver
from apm.sim.examples import get_examples, check_examples
from apm.sim.settings import N_SIMS2 as N_SIMS
from apm.sim.defs import SIM_ITERS
------------------

[0;31m---------------------------------------------------------------------------[0m
[0;31mModuleNotFoundError[0m                       Traceback (most recent call last)
[0;32m<ipython-input-2-bd254a3bf27f>[0m in [0;36m<module>[0;34m[0m
[1;32m      3[0m [0msys[0m[0;34m.[0m[0mpath[0m[0;34m.[0m[0mappend[0m[0;34m([0m[0mstr[0m[0;34m([0m[0mPath[0m[0;34m([0m[0;34m'..'[0m[0;34m)[0m[0;34m.[0m[0mresolve[0m[0;34m([0m[0;34m)[0m[0;34m)[0m[0;34m)[0m[0;34m[0m[0;34m[0m[0m
[1;32m      4[0m [0;34m[0m[0m
[0;32m----> 5[0;31m [0;32mfrom[0m [0mapm[0m[0;34m.[0m[0mio[0m [0;32mimport[0m [0mAPMDB[0m[0;34m[0m[0;34m[0m[0m
[0m[1;32m      6[0m [0;32mfrom[0m [0mapm[0m[0;34m.[0m[0mrun[0m [0;32mimport[0m [0mrun_sims[0m[0;34m,[0m [0mrun_sims_load[0m[0;34m[0m[0;34m[0m[0m
[1;32m      7[0m [0;32mfrom[0m [0mapm[0m[0;34m.[0m[0mmethods[0m [0;32mimport[0m [0mlyapunov[0m[0;34m[0m[0;34m[0m[0m

[0;31mModuleNotFoundError[0m: No module named 'apm'
ModuleNotFoundError: No module named 'apm'

